{"content": {"suites": {"0": {"status": {"total_pass": 2, "total_skip": 0, "total_xpass": 0, "total_xfail": 0, "total_rerun": 0, "total_fail": 1, "total_error": 0}, "tests": {"0": {"status": "PASS", "message": "", "test_name": "test_log", "rerun": "0"}, "1": {"status": "PASS", "message": "", "test_name": "test_log", "rerun": "0"}, "2": {"status": "FAIL", "message": "           ConnectionRefusedError: [Errno 111] Connection refused\n       urllib3.exceptions.NewConnectionError: <urllib3.connection.HTTPConnection object at 0x7fdb2cfca3a0>: Failed to establish a new connection: [Errno 111] Connection refused\n       urllib3.exceptions.MaxRetryError: HTTPConnectionPool(host='localhost', port=57489): Max retries exceeded with url: /session/17b43a2fb6861af4aa8a7f004cfc18be/url (Caused by NewConnectionError('<urllib3.connection.HTTPConnection object at 0x7fdb2cfca3a0>: Failed to establish a new connection: [Errno 111] Connection refused'))\n", "test_name": "test_login", "rerun": "0"}}, "suite_name": "test_deskhomepage.py"}}}, "date": "September 07, 2022", "start_time": 1662534953.9883559, "total_suite": 1, "status": "FAIL", "status_list": {"pass": "2", "fail": "1", "skip": "0", "error": "0", "xpass": "0", "xfail": "0", "rerun": "0"}, "total_tests": "3"}